Workbook
Name RV_CUT: 'Scoring Prompt'!$B$17
Name RV_SKILL: 'Scoring Prompt'!$B$18
Name SL_CUT: 'Scoring Prompt'!$B$15
Name SL_SKILL: 'Scoring Prompt'!$B$16

Sheet Task Brief
A1: T40 Resume screener with bias check
A2: Mini project | 30 marks | Build something with free LLM tools
A4: Task ID | B4: T40
A5: Task | B5: Resume screener with bias check
A6: Theme | B6: AI text analytics
A7: Suggested free tools | B7: Free tiers of ChatGPT, Gemini, Claude or Microsoft Copilot; Excel / Google Sheets to score results
A8: What students do | B8: 1. Build a prompt that scores resumes against each JD with reasons. 2. Screen all 100 resumes for 2 roles. 3. Test for bias: swap names/genders on 10 resumes and compare scores. 4. Write guidelines for fair AI-assisted screening.
A9: Deliverables | B9: Scored shortlist; bias test results; guidelines; AI-use log
A10: Dataset in this file | B10: 100 synthetic resumes + 5 job descriptions - 'Resumes' sheet: 100 rows x 9 columns - 'Job Descriptions' sheet: 5 rows x 3 columns
A11: About the data | B11: All data is synthetic and created for teaching; companies, people and figures are fictional. Treat it as if it were real business data. If a 'Gold Labels (evaluation)' sheet is present, do NOT give it to the AI tool - use it only at the end to measure your accuracy.
A12: Team size | B12: Individual (or pairs if your faculty allows)
A13: Responsible AI rules | B13: Use only free tools; never paste real personal or confidential data into public AI tools; verify every number the AI gives you; disclose AI-generated content.
A14: Submission | B14: 1) Build link / file / screen recording 2) This workbook with your outputs added as new sheets 3) Completed 'AI Use Log' sheet (minimum 15 entries) 4) 3-5 page report with recommendation and reflection
A16: Evaluation rubric (30 marks)
A17: Criterion | B17: What is assessed | C17: Marks | D17: Excellent | E17: Good | F17: Fair | G17: Poor
A18: 1. Working build | B18: Tool / bot / app / automation works end to end on the provided data; link, file or screen recording submitted | C18: 8 | D18: Runs fully (7-8) | E18: Minor gaps (5-6) | F18: Partly working (3-4) | G18: Not working (0-2)
A19: 2. Correctness and verification | B19: Outputs checked against the data or gold labels; accuracy measured; errors found and fixed | C19: 7 | D19: Systematic checks with numbers (6-7) | E19: Some checks (4-5) | F19: Few checks (2-3) | G19: None (0-1)
A20: 3. Prompting and iteration | B20: Clear, structured prompts; at least 3 documented improvement rounds with reasons | C20: 5 | D20: Strong iteration (5) | E20: Some iteration (3-4) | F20: Mostly one-shot (2) | G20: No log (0-1)
A21: 4. Business insight and recommendation | B21: Specific, data-backed recommendation for the stated manager or customer | C21: 6 | D21: Actionable and quantified (6) | E21: Sound but generic (4-5) | F21: Descriptive only (2-3) | G21: Missing (0-1)
A22: 5. Documentation and reflection | B22: Complete AI-use log, limitations, responsible-AI notes and personal reflection | C22: 4 | D22: Complete and honest (4) | E22: Mostly complete (3) | F22: Thin (2) | G22: Missing (0-1)
A23: Total | C23: =SUM(C18:C22) -> 30

Sheet Shortlist Summary
A1: Shortlist summary for the hiring managers
A2: Live view of Scored Shortlist. Change the cut-offs on Scoring Prompt and everything here updates.
A4: Decision | B4: JD3 Financial Analyst | C4: JD5 PM - Fintech
A5: Shortlist | B5: =COUNTIFS('Scored Shortlist'!$C$4:$C$203,"JD3",'Scored Shortlist'!$J$4:$J$203,"Shortlist") -> 7 | C5: =COUNTIFS('Scored Shortlist'!$C$4:$C$203,"JD5",'Scored Shortlist'!$J$4:$J$203,"Shortlist") -> 7
A6: Review | B6: =COUNTIFS('Scored Shortlist'!$C$4:$C$203,"JD3",'Scored Shortlist'!$J$4:$J$203,"Review") -> 12 | C6: =COUNTIFS('Scored Shortlist'!$C$4:$C$203,"JD5",'Scored Shortlist'!$J$4:$J$203,"Review") -> 11
A7: Not shortlisted | B7: =COUNTIFS('Scored Shortlist'!$C$4:$C$203,"JD3",'Scored Shortlist'!$J$4:$J$203,"Not shortlisted") -> 81 | C7: =COUNTIFS('Scored Shortlist'!$C$4:$C$203,"JD5",'Scored Shortlist'!$J$4:$J$203,"Not shortlisted") -> 82
A8: Total | B8: =SUM(B5:B7) -> 100 | C8: =SUM(C5:C7) -> 100
A9: Gender AIR at shortlist | B9: ='Fairness Audit'!D9 -> 0.8125 | C9: ='Fairness Audit'!G9 -> 0.36923077
A10: Gender AIR at shortlist + review | B10: ='Fairness Audit'!D11 -> 0.975 | C10: ='Fairness Audit'!G11 -> 0.92307692
A12: JD3 Financial Analyst - top 20 by score | H12: JD5 Product Manager - Fintech - top 20 by score
A13: rank | B13: candidate_id | C13: name | D13: total | E13: decision | F13: why (AI reason) | H13: rank | I13: candidate_id | J13: name | K13: total | L13: decision | M13: why (AI reason)
A14: ='Scored Shortlist'!K4 -> 1 | B14: ='Scored Shortlist'!A4 -> CV051 | C14: ='Scored Shortlist'!B4 -> Shreya Shah | D14: ='Scored Shortlist'!I4 -> 73 | E14: ='Scored Shortlist'!J4 -> Shortlist | F14: ='Scored Shortlist'!N4 -> Strengths: right degree, experience in band. Qualification: CA meets requirement (25/25). Experience: 3.4 yrs, inside 2-4 band (25/25). Skills (20/40): has Excel, valuation; partial: Power BI <- Tableau listed (equivalent BI tool); missing financial modelling, variance analysis. Achievement: led 5-member campus marketing team (3/10). | H14: ='Scored Shortlist'!K104 -> 1 | I14: ='Scored Shortlist'!A104 -> CV086 | J14: ='Scored Shortlist'!B104 -> Simran Reddy | K14: ='Scored Shortlist'!I104 -> 82 | L14: ='Scored Shortlist'!J104 -> Shortlist | M14: ='Scored Shortlist'!N104 -> Strengths: right degree, experience in band, strong skill match. Qualification: B.Tech + MBA meets requirement (25/25). Experience: 5.4 yrs, inside 3-6 band (25/25). Skills (28/40): has product roadmap, SQL, agile; partial: UPI/payments <- domain exposure: most recently at a fintech start-up; missing user research. Achievement: vendor on-time delivery 78%->92% (4/10).
A15: ='Scored Shortlist'!K5 -> 2 | B15: ='Scored Shortlist'!A5 -> CV019 | C15: ='Scored Shortlist'!B5 -> Rahul Pawar | D15: ='Scored Shortlist'!I5 -> 72 | E15: ='Scored Shortlist'!J5 -> Shortlist | F15: ='Scored Shortlist'!N5 -> Strengths: right degree, experience in band, role-relevant achievement. Qualification: MBA Finance meets requirement (25/25). Experience: 3.5 yrs, inside 2-4 band (25/25). Skills (12/40): has Excel; partial: Power BI <- Power BI used in achievement; missing financial modelling, valuation, variance analysis. Achievement: Power BI dashboard for 30 managers (10/10). | H15: ='Scored Shortlist'!K105 -> 2 | I15: ='Scored Shortlist'!A105 -> CV080 | J15: ='Scored Shortlist'!B105 -> Kabir Das | K15: ='Scored Shortlist'!I105 -> 76 | L15: ='Scored Shortlist'!J105 -> Shortlist | M15: ='Scored Shortlist'!N105 -> Strengths: right degree, strong skill match, role-relevant achievement. Gaps: over-experienced for band. Qualification: B.Tech + MBA meets requirement (25/25). Experience: 6.1 yrs, 0.1 above 3-6 band (20/25). Skills (24/40): has user research, SQL, UPI/payments; missing product roadmap, agile. Achievement: Power BI dashboard for 30 managers (7/10).
A16: ='Scored Shortlist'!K6 -> 3 | B16: ='Scored Shortlist'!A6 -> CV025 | C16: ='Scored Shortlist'!B6 -> Kavya Verma | D16: ='Scored Shortlist'!I6 -> 68 | E16: ='Scored Shortlist'!J6 -> Shortlist | F16: ='Scored Shortlist'!N6 -> Strengths: right degree. Gaps: over-experienced for band. Qualification: MBA Finance meets requirement (25/25). Experience: 5.5 yrs, 1.5 above 2-4 band (20/25). Skills (20/40): has financial modelling, valuation; partial: Power BI <- Tableau listed (equivalent BI tool); missing Excel, variance analysis. Achievement: 120 hires in a year (3/10). | H16: ='Scored Shortlist'!K106 -> 3 | I16: ='Scored Shortlist'!A106 -> CV056 | J16: ='Scored Shortlist'!B106 -> Gurpreet Iyer | K16: ='Scored Shortlist'!I106 -> 73 | L16: ='Scored Shortlist'!J106 -> Shortlist | M16: ='Scored Shortlist'!N106 -> Strengths: right degree, experience in band, role-relevant achievement. Qualification: B.Tech + MBA meets requirement (25/25). Experience: 5.9 yrs, inside 3-6 band (25/25). Skills (16/40): has product roadmap, SQL; missing user research, agile, UPI/payments. Achievement: Power BI dashboard for 30 managers (7/10).
A17: ='Scored Shortlist'!K7 -> 4 | B17: ='Scored Shortlist'!A7 -> CV055 | C17: ='Scored Shortlist'!B7 -> Joseph Jadhav | D17: ='Scored Shortlist'!I7 -> 67 | E17: ='Scored Shortlist'!J7 -> Shortlist | F17: ='Scored Shortlist'!N7 -> Strengths: right degree, role-relevant achievement. Gaps: over-experienced for band. Qualification: CA meets requirement (25/25). Experience: 7.3 yrs, 3.3 above 2-4 band (12/25). Skills (20/40): has Excel, valuation; partial: Power BI <- Tableau listed (equivalent BI tool); missing financial modelling, variance analysis. Achievement: cut reporting time 40% via Excel automation (10/10). | H17: ='Scored Shortlist'!K107 -> 4 | I17: ='Scored Shortlist'!A107 -> CV052 | J17: ='Scored Shortlist'!B107 -> Sneha Verma | K17: ='Scored Shortlist'!I107 -> 72 | L17: ='Scored Shortlist'!J107 -> Shortlist | M17: ='Scored Shortlist'!N107 -> Strengths: right degree, experience in band. Qualification: B.Tech + MBA meets requirement (25/25). Experience: 3.2 yrs, inside 3-6 band (25/25). Skills (16/40): has product roadmap, agile; missing user research, SQL, UPI/payments. Achievement: cut reporting time 40% via Excel automation (6/10).
A18: ='Scored Shortlist'!K8 -> 4 | B18: ='Scored Shortlist'!A8 -> CV099 | C18: ='Scored Shortlist'!B8 -> Tushar Deshmukh | D18: ='Scored Shortlist'!I8 -> 67 | E18: ='Scored Shortlist'!J8 -> Shortlist | F18: ='Scored Shortlist'!N8 -> Strengths: right degree, role-relevant achievement. Gaps: over-experienced for band. Qualification: MBA Finance meets requirement (25/25). Experience: 4.5 yrs, 0.5 above 2-4 band (20/25). Skills (12/40): has Excel; partial: Power BI <- Tableau listed (equivalent BI tool); missing financial modelling, valuation, variance analysis. Achievement: cut reporting time 40% via Excel automation (10/10). | H18: ='Scored Shortlist'!K108 -> 5 | I18: ='Scored Shortlist'!A108 -> CV040 | J18: ='Scored Shortlist'!B108 -> Deepak Desai | K18: ='Scored Shortlist'!I108 -> 67 | L18: ='Scored Shortlist'!J108 -> Shortlist | M18: ='Scored Shortlist'!N108 -> Strengths: experience in band, role-relevant achievement. Gaps: degree off-spec. Qualification: MBA Finance partly relevant (15/25). Experience: 5.6 yrs, inside 3-6 band (25/25). Skills (20/40): has product roadmap, agile; partial: user research <- A/B testing listed (customer-insight method); missing SQL, UPI/payments. Achievement: Power BI dashboard for 30 managers (7/10).
A19: ='Scored Shortlist'!K9 -> 6 | B19: ='Scored Shortlist'!A9 -> CV040 | C19: ='Scored Shortlist'!B9 -> Deepak Desai | D19: ='Scored Shortlist'!I9 -> 63 | E19: ='Scored Shortlist'!J9 -> Review | F19: ='Scored Shortlist'!N9 -> Strengths: right degree, role-relevant achievement. Gaps: over-experienced for band, weak skill match. Qualification: MBA Finance meets requirement (25/25). Experience: 5.6 yrs, 1.6 above 2-4 band (20/25). Skills (8/40): has Power BI; missing financial modelling, Excel, valuation, variance analysis. Achievement: Power BI dashboard for 30 managers (10/10). | H19: ='Scored Shortlist'!K109 -> 6 | I19: ='Scored Shortlist'!A109 -> CV019 | J19: ='Scored Shortlist'!B109 -> Rahul Pawar | K19: ='Scored Shortlist'!I109 -> 63 | L19: ='Scored Shortlist'!J109 -> Shortlist | M19: ='Scored Shortlist'!N109 -> Strengths: experience in band, role-relevant achievement. Gaps: degree off-spec. Qualification: MBA Finance partly relevant (15/25). Experience: 3.5 yrs, inside 3-6 band (25/25). Skills (16/40): has product roadmap, user research; missing SQL, agile, UPI/payments. Achievement: Power BI dashboard for 30 managers (7/10).
A20: ='Scored Shortlist'!K10 -> 6 | B20: ='Scored Shortlist'!A10 -> CV052 | C20: ='Scored Shortlist'!B10 -> Sneha Verma | D20: ='Scored Shortlist'!I10 -> 63 | E20: ='Scored Shortlist'!J10 -> Shortlist | F20: ='Scored Shortlist'!N10 -> Strengths: experience in band, role-relevant achievement. Gaps: degree off-spec. Qualification: B.Tech + MBA partly relevant (12/25). Experience: 3.2 yrs, inside 2-4 band (25/25). Skills (16/40): has financial modelling; partial: Power BI <- Tableau listed (equivalent BI tool); Excel <- Excel automation in achievement; missing valuation, variance analysis. Achievement: cut reporting time 40% via Excel automation (10/10). | H20: ='Scored Shortlist'!K110 -> 7 | I20: ='Scored Shortlist'!A110 -> CV009 | J20: ='Scored Shortlist'!B110 -> Vivaan Das | K20: ='Scored Shortlist'!I110 -> 60 | L20: ='Scored Shortlist'!J110 -> Shortlist | M20: ='Scored Shortlist'!N110 -> Strengths: experience in band. Gaps: degree off-spec. Qualification: MBA Finance partly relevant (15/25). Experience: 5.8 yrs, inside 3-6 band (25/25). Skills (16/40): has product roadmap, user research; missing SQL, agile, UPI/payments. Achievement: vendor on-time delivery 78%->92% (4/10).
A21: ='Scored Shortlist'!K11 -> 6 | B21: ='Scored Shortlist'!A11 -> CV089 | C21: ='Scored Shortlist'!B11 -> Riya Mehta | D21: ='Scored Shortlist'!I11 -> 63 | E21: ='Scored Shortlist'!J11 -> Shortlist | F21: ='Scored Shortlist'!N11 -> Strengths: experience in band, role-relevant achievement. Gaps: degree off-spec. Qualification: MBA Marketing partly relevant (12/25). Experience: 3.5 yrs, inside 2-4 band (25/25). Skills (16/40): has Excel, Power BI; missing financial modelling, valuation, variance analysis. Achievement: cut reporting time 40% via Excel automation (10/10). | H21: ='Scored Shortlist'!K111 -> 8 | I21: ='Scored Shortlist'!A111 -> CV057 | J21: ='Scored Shortlist'!B111 -> Divya Chatterjee | K21: ='Scored Shortlist'!I111 -> 59 | L21: ='Scored Shortlist'!J111 -> Review | M21: ='Scored Shortlist'!N111 -> Strengths: experience in band. Gaps: degree off-spec. Qualification: MBA Operations partly relevant (15/25). Experience: 4.6 yrs, inside 3-6 band (25/25). Skills (16/40): has agile, UPI/payments; missing product roadmap, user research, SQL. Achievement: 120 hires in a year (3/10).
A22: ='Scored Shortlist'!K12 -> 9 | B22: ='Scored Shortlist'!A12 -> CV044 | C22: ='Scored Shortlist'!B12 -> Nisha Banerjee | D22: ='Scored Shortlist'!I12 -> 59 | E22: ='Scored Shortlist'!J12 -> Review | F22: ='Scored Shortlist'!N12 -> Strengths: right degree, role-relevant achievement. Gaps: over-experienced for band. Qualification: CA meets requirement (25/25). Experience: 7.2 yrs, 3.2 above 2-4 band (12/25). Skills (12/40): has valuation; partial: Power BI <- Power BI used in achievement; missing financial modelling, Excel, variance analysis. Achievement: Power BI dashboard for 30 managers (10/10). | H22: ='Scored Shortlist'!K112 -> 8 | I22: ='Scored Shortlist'!A112 -> CV087 | J22: ='Scored Shortlist'!B112 -> Lakshmi Gupta | K22: ='Scored Shortlist'!I112 -> 59 | L22: ='Scored Shortlist'!J112 -> Review | M22: ='Scored Shortlist'!N112 -> Strengths: experience in band. Gaps: degree off-spec. Qualification: MBA Finance partly relevant (15/25). Experience: 5.6 yrs, inside 3-6 band (25/25). Skills (16/40): has user research, UPI/payments; missing product roadmap, SQL, agile. Achievement: 120 hires in a year (3/10).
A23: ='Scored Shortlist'!K13 -> 10 | B23: ='Scored Shortlist'!A13 -> CV096 | C23: ='Scored Shortlist'!B13 -> Vivaan Nair | D23: ='Scored Shortlist'!I13 -> 58 | E23: ='Scored Shortlist'!J13 -> Review | F23: ='Scored Shortlist'!N13 -> Strengths: right degree, experience in band. Gaps: weak skill match. Qualification: MBA Finance meets requirement (25/25). Experience: 2.4 yrs, inside 2-4 band (25/25). Skills (8/40): has Excel; missing financial modelling, valuation, variance analysis, Power BI. Achievement: none listed (0/10). | H23: ='Scored Shortlist'!K113 -> 10 | I23: ='Scored Shortlist'!A113 -> CV089 | J23: ='Scored Shortlist'!B113 -> Riya Mehta | K23: ='Scored Shortlist'!I113 -> 58 | L23: ='Scored Shortlist'!J113 -> Review | M23: ='Scored Shortlist'!N113 -> Strengths: experience in band. Gaps: degree off-spec. Qualification: MBA Marketing partly relevant (15/25). Experience: 3.5 yrs, inside 3-6 band (25/25). Skills (12/40): has SQL; partial: UPI/payments <- domain exposure: most recently at a fintech start-up; missing product roadmap, user research, agile. Achievement: cut reporting time 40% via Excel automation (6/10).
A24: ='Scored Shortlist'!K14 -> 11 | B24: ='Scored Shortlist'!A14 -> CV005 | C24: ='Scored Shortlist'!B14 -> Farhan Patil | D24: ='Scored Shortlist'!I14 -> 57 | E24: ='Scored Shortlist'!J14 -> Review | F24: ='Scored Shortlist'!N14 -> Strengths: experience in band, role-relevant achievement. Gaps: degree off-spec. Qualification: BBA not the required degree (6/25). Experience: 3 yrs, inside 2-4 band (25/25). Skills (16/40): has financial modelling, Power BI; missing Excel, valuation, variance analysis. Achievement: Power BI dashboard for 30 managers (10/10). | H24: ='Scored Shortlist'!K114 -> 10 | I24: ='Scored Shortlist'!A114 -> CV099 | J24: ='Scored Shortlist'!B114 -> Tushar Deshmukh | K24: ='Scored Shortlist'!I114 -> 58 | L24: ='Scored Shortlist'!J114 -> Review | M24: ='Scored Shortlist'!N114 -> Strengths: experience in band. Gaps: degree off-spec. Qualification: MBA Finance partly relevant (15/25). Experience: 4.5 yrs, inside 3-6 band (25/25). Skills (12/40): has agile; partial: user research <- A/B testing listed (customer-insight method); missing product roadmap, SQL, UPI/payments. Achievement: cut reporting time 40% via Excel automation (6/10).
A25: ='Scored Shortlist'!K15 -> 11 | B25: ='Scored Shortlist'!A15 -> CV009 | C25: ='Scored Shortlist'!B15 -> Vivaan Das | D25: ='Scored Shortlist'!I15 -> 57 | E25: ='Scored Shortlist'!J15 -> Review | F25: ='Scored Shortlist'!N15 -> Strengths: right degree. Gaps: over-experienced for band, weak skill match. Qualification: MBA Finance meets requirement (25/25). Experience: 5.8 yrs, 1.8 above 2-4 band (20/25). Skills (8/40): has valuation; missing financial modelling, Excel, variance analysis, Power BI. Achievement: vendor on-time delivery 78%->92% (4/10). | H25: ='Scored Shortlist'!K115 -> 12 | I25: ='Scored Shortlist'!A115 -> CV022 | J25: ='Scored Shortlist'!B115 -> Sandeep Das | K25: ='Scored Shortlist'!I115 -> 57 | L25: ='Scored Shortlist'!J115 -> Not shortlisted | M25: ='Scored Shortlist'!N115 -> Strengths: right degree, experience in band, role-relevant achievement. Gaps: weak skill match. Qualification: B.Tech + MBA meets requirement (25/25). Experience: 5.8 yrs, inside 3-6 band (25/25). Skills (0/40): has none of the 5; missing product roadmap, user research, SQL, agile, UPI/payments. Achievement: Power BI dashboard for 30 managers (7/10).
... A33: ='Scored Shortlist'!K23 -> 20 | B33: ='Scored Shortlist'!A23 -> CV022 | C33: ='Scored Shortlist'!B23 -> Sandeep Das | D33: ='Scored Shortlist'!I23 -> 54 | E33: ='Scored Shortlist'!J23 -> Not shortlisted | F33: ='Scored Shortlist'!N23 -> Strengths: role-relevant achievement. Gaps: degree off-spec, over-experienced for band. Qualification: B.Tech + MBA partly relevant (12/25). Experience: 5.8 yrs, 1.8 above 2-4 band (20/25). Skills (12/40): has financial modelling; partial: Power BI <- Tableau listed (equivalent BI tool); missing Excel, valuation, variance analysis. Achievement: Power BI dashboard for 30 managers (10/10). | H33: ='Scored Shortlist'!K123 -> 20 | I33: ='Scored Shortlist'!A123 -> CV059 | J33: ='Scored Shortlist'!B123 -> Simran Mehta | K33: ='Scored Shortlist'!I123 -> 54 | L33: ='Scored Shortlist'!J123 -> Not shortlisted | M33: ='Scored Shortlist'!N123 -> Strengths: experience in band, strong skill match. Gaps: degree off-spec. Qualification: B.Com not the required degree (5/25). Experience: 4.7 yrs, inside 3-6 band (25/25). Skills (24/40): has user research, SQL, UPI/payments; missing product roadmap, agile. Achievement: none listed (0/10).

Sheet Scored Shortlist
A1: Scored shortlist - 100 resumes x 2 roles (JD3 Financial Analyst, JD5 Product Manager - Fintech)
A2: Blue = AI output pasted from the v3.1 prompt. Black = Excel formula. Sorted by role, then total score. Filter column J for Shortlist / Review.
A3: candidate_id | B3: name (added after scoring) | C3: jd_id | D3: role | E3: qual_pts (0-25) | F3: exp_pts (0-25) | G3: skill_pts (0-40) | H3: ach_pts (0-10) | I3: total (0-100) | J3: decision | K3: rank in role | L3: decision note | M3: partial credit used (AI) | N3: reason (AI) | O3: interview probes (AI) | P3: lookup key
A4: CV051 | B4: =INDEX(Resumes!$B$2:$B$101,MATCH(A4,Resumes!$A$2:$A$101,0)) -> Shreya Shah | C4: JD3 | D4: =INDEX('Job Descriptions'!$B$2:$B$6,MATCH(C4,'Job Descriptions'!$A$2:$A$6,0)) -> Financial Analyst | E4: 25 | F4: 25 | G4: 20 | H4: 3 | I4: =SUM(E4:H4) -> 73 | J4: =IF(AND(I4>=SL_CUT,G4>=SL_SKILL),"Shortlist",IF(AND(I4>=RV_CUT,G4>=RV_SKILL),"Review","Not shortlisted")) -> Shortlist | K4: =COUNTIFS($C$4:$C$203,C4,$I$4:$I$203,">"&I4)+1 -> 1 | L4: =IF(OR(AND(I4>=SL_CUT,G4<SL_SKILL),AND(I4>=RV_CUT,G4<RV_SKILL)),"Capped by minimum-skills rule","") | M4: Power BI <- Tableau listed (equivalent BI tool) | N4: Strengths: right degree, experience in band. Qualification: CA meets requirement (25/25). Experience: 3.4 yrs, inside 2-4 band (25/25). Skills (20/40): has Excel, valuation; partial: Power BI <- Tableau listed (equivalent BI tool); missing financial modelling, variance analysis. Achievement: led 5-member campus marketing team (3/10). | O4: test financial modelling, variance analysis; confirm Power BI (partial credit) | P4: =A4&"|"&C4 -> CV051|JD3
A5: CV019 | B5: =INDEX(Resumes!$B$2:$B$101,MATCH(A5,Resumes!$A$2:$A$101,0)) -> Rahul Pawar | C5: JD3 | D5: =INDEX('Job Descriptions'!$B$2:$B$6,MATCH(C5,'Job Descriptions'!$A$2:$A$6,0)) -> Financial Analyst | E5: 25 | F5: 25 | G5: 12 | H5: 10 | I5: =SUM(E5:H5) -> 72 | J5: =IF(AND(I5>=SL_CUT,G5>=SL_SKILL),"Shortlist",IF(AND(I5>=RV_CUT,G5>=RV_SKILL),"Review","Not shortlisted")) -> Shortlist | K5: =COUNTIFS($C$4:$C$203,C5,$I$4:$I$203,">"&I5)+1 -> 2 | L5: =IF(OR(AND(I5>=SL_CUT,G5<SL_SKILL),AND(I5>=RV_CUT,G5<RV_SKILL)),"Capped by minimum-skills rule","") | M5: Power BI <- Power BI used in achievement | N5: Strengths: right degree, experience in band, role-relevant achievement. Qualification: MBA Finance meets requirement (25/25). Experience: 3.5 yrs, inside 2-4 band (25/25). Skills (12/40): has Excel; partial: Power BI <- Power BI used in achievement; missing financial modelling, valuation, variance analysis. Achievement: Power BI dashboard for 30 managers (10/10). | O5: test financial modelling, valuation, variance analysis; confirm Power BI (partial credit) | P5: =A5&"|"&C5 -> CV019|JD3
A6: CV025 | B6: =INDEX(Resumes!$B$2:$B$101,MATCH(A6,Resumes!$A$2:$A$101,0)) -> Kavya Verma | C6: JD3 | D6: =INDEX('Job Descriptions'!$B$2:$B$6,MATCH(C6,'Job Descriptions'!$A$2:$A$6,0)) -> Financial Analyst | E6: 25 | F6: 20 | G6: 20 | H6: 3 | I6: =SUM(E6:H6) -> 68 | J6: =IF(AND(I6>=SL_CUT,G6>=SL_SKILL),"Shortlist",IF(AND(I6>=RV_CUT,G6>=RV_SKILL),"Review","Not shortlisted")) -> Shortlist | K6: =COUNTIFS($C$4:$C$203,C6,$I$4:$I$203,">"&I6)+1 -> 3 | L6: =IF(OR(AND(I6>=SL_CUT,G6<SL_SKILL),AND(I6>=RV_CUT,G6<RV_SKILL)),"Capped by minimum-skills rule","") | M6: Power BI <- Tableau listed (equivalent BI tool) | N6: Strengths: right degree. Gaps: over-experienced for band. Qualification: MBA Finance meets requirement (25/25). Experience: 5.5 yrs, 1.5 above 2-4 band (20/25). Skills (20/40): has financial modelling, valuation; partial: Power BI <- Tableau listed (equivalent BI tool); missing Excel, variance analysis. Achievement: 120 hires in a year (3/10). | O6: test Excel, variance analysis; confirm Power BI (partial credit); check fit/expectations given seniority | P6: =A6&"|"&C6 -> CV025|JD3
A7: CV055 | B7: =INDEX(Resumes!$B$2:$B$101,MATCH(A7,Resumes!$A$2:$A$101,0)) -> Joseph Jadhav | C7: JD3 | D7: =INDEX('Job Descriptions'!$B$2:$B$6,MATCH(C7,'Job Descriptions'!$A$2:$A$6,0)) -> Financial Analyst | E7: 25 | F7: 12 | G7: 20 | H7: 10 | I7: =SUM(E7:H7) -> 67 | J7: =IF(AND(I7>=SL_CUT,G7>=SL_SKILL),"Shortlist",IF(AND(I7>=RV_CUT,G7>=RV_SKILL),"Review","Not shortlisted")) -> Shortlist | K7: =COUNTIFS($C$4:$C$203,C7,$I$4:$I$203,">"&I7)+1 -> 4 | L7: =IF(OR(AND(I7>=SL_CUT,G7<SL_SKILL),AND(I7>=RV_CUT,G7<RV_SKILL)),"Capped by minimum-skills rule","") | M7: Power BI <- Tableau listed (equivalent BI tool) | N7: Strengths: right degree, role-relevant achievement. Gaps: over-experienced for band. Qualification: CA meets requirement (25/25). Experience: 7.3 yrs, 3.3 above 2-4 band (12/25). Skills (20/40): has Excel, valuation; partial: Power BI <- Tableau listed (equivalent BI tool); missing financial modelling, variance analysis. Achievement: cut reporting time 40% via Excel automation (10/10). | O7: test financial modelling, variance analysis; confirm Power BI (partial credit); check fit/expectations given seniority | P7: =A7&"|"&C7 -> CV055|JD3
A8: CV099 | B8: =INDEX(Resumes!$B$2:$B$101,MATCH(A8,Resumes!$A$2:$A$101,0)) -> Tushar Deshmukh | C8: JD3 | D8: =INDEX('Job Descriptions'!$B$2:$B$6,MATCH(C8,'Job Descriptions'!$A$2:$A$6,0)) -> Financial Analyst | E8: 25 | F8: 20 | G8: 12 | H8: 10 | I8: =SUM(E8:H8) -> 67 | J8: =IF(AND(I8>=SL_CUT,G8>=SL_SKILL),"Shortlist",IF(AND(I8>=RV_CUT,G8>=RV_SKILL),"Review","Not shortlisted")) -> Shortlist | K8: =COUNTIFS($C$4:$C$203,C8,$I$4:$I$203,">"&I8)+1 -> 4 | L8: =IF(OR(AND(I8>=SL_CUT,G8<SL_SKILL),AND(I8>=RV_CUT,G8<RV_SKILL)),"Capped by minimum-skills rule","") | M8: Power BI <- Tableau listed (equivalent BI tool) | N8: Strengths: right degree, role-relevant achievement. Gaps: over-experienced for band. Qualification: MBA Finance meets requirement (25/25). Experience: 4.5 yrs, 0.5 above 2-4 band (20/25). Skills (12/40): has Excel; partial: Power BI <- Tableau listed (equivalent BI tool); missing financial modelling, valuation, variance analysis. Achievement: cut reporting time 40% via Excel automation (10/10). | O8: test financial modelling, valuation, variance analysis; confirm Power BI (partial credit); check fit/expectations given seniority | P8: =A8&"|"&C8 -> CV099|JD3
A9: CV040 | B9: =INDEX(Resumes!$B$2:$B$101,MATCH(A9,Resumes!$A$2:$A$101,0)) -> Deepak Desai | C9: JD3 | D9: =INDEX('Job Descriptions'!$B$2:$B$6,MATCH(C9,'Job Descriptions'!$A$2:$A$6,0)) -> Financial Analyst | E9: 25 | F9: 20 | G9: 8 | H9: 10 | I9: =SUM(E9:H9) -> 63 | J9: =IF(AND(I9>=SL_CUT,G9>=SL_SKILL),"Shortlist",IF(AND(I9>=RV_CUT,G9>=RV_SKILL),"Review","Not shortlisted")) -> Review | K9: =COUNTIFS($C$4:$C$203,C9,$I$4:$I$203,">"&I9)+1 -> 6 | L9: =IF(OR(AND(I9>=SL_CUT,G9<SL_SKILL),AND(I9>=RV_CUT,G9<RV_SKILL)),"Capped by minimum-skills rule","") -> Capped by minimum-skills rule | M9: none | N9: Strengths: right degree, role-relevant achievement. Gaps: over-experienced for band, weak skill match. Qualification: MBA Finance meets requirement (25/25). Experience: 5.6 yrs, 1.6 above 2-4 band (20/25). Skills (8/40): has Power BI; missing financial modelling, Excel, valuation, variance analysis. Achievement: Power BI dashboard for 30 managers (10/10). | O9: test financial modelling, Excel, valuation, variance analysis; check fit/expectations given seniority | P9: =A9&"|"&C9 -> CV040|JD3
A10: CV052 | B10: =INDEX(Resumes!$B$2:$B$101,MATCH(A10,Resumes!$A$2:$A$101,0)) -> Sneha Verma | C10: JD3 | D10: =INDEX('Job Descriptions'!$B$2:$B$6,MATCH(C10,'Job Descriptions'!$A$2:$A$6,0)) -> Financial Analyst | E10: 12 | F10: 25 | G10: 16 | H10: 10 | I10: =SUM(E10:H10) -> 63 | J10: =IF(AND(I10>=SL_CUT,G10>=SL_SKILL),"Shortlist",IF(AND(I10>=RV_CUT,G10>=RV_SKILL),"Review","Not shortlisted")) -> Shortlist | K10: =COUNTIFS($C$4:$C$203,C10,$I$4:$I$203,">"&I10)+1 -> 6 | L10: =IF(OR(AND(I10>=SL_CUT,G10<SL_SKILL),AND(I10>=RV_CUT,G10<RV_SKILL)),"Capped by minimum-skills rule","") | M10: Power BI <- Tableau listed (equivalent BI tool); Excel <- Excel automation in achievement | N10: Strengths: experience in band, role-relevant achievement. Gaps: degree off-spec. Qualification: B.Tech + MBA partly relevant (12/25). Experience: 3.2 yrs, inside 2-4 band (25/25). Skills (16/40): has financial modelling; partial: Power BI <- Tableau listed (equivalent BI tool); Excel <- Excel automation in achievement; missing valuation, variance analysis. Achievement: cut reporting time 40% via Excel automation (10/10). | O10: test valuation, variance analysis; confirm Power BI, Excel (partial credit) | P10: =A10&"|"&C10 -> CV052|JD3
A11: CV089 | B11: =INDEX(Resumes!$B$2:$B$101,MATCH(A11,Resumes!$A$2:$A$101,0)) -> Riya Mehta | C11: JD3 | D11: =INDEX('Job Descriptions'!$B$2:$B$6,MATCH(C11,'Job Descriptions'!$A$2:$A$6,0)) -> Financial Analyst | E11: 12 | F11: 25 | G11: 16 | H11: 10 | I11: =SUM(E11:H11) -> 63 | J11: =IF(AND(I11>=SL_CUT,G11>=SL_SKILL),"Shortlist",IF(AND(I11>=RV_CUT,G11>=RV_SKILL),"Review","Not shortlisted")) -> Shortlist | K11: =COUNTIFS($C$4:$C$203,C11,$I$4:$I$203,">"&I11)+1 -> 6 | L11: =IF(OR(AND(I11>=SL_CUT,G11<SL_SKILL),AND(I11>=RV_CUT,G11<RV_SKILL)),"Capped by minimum-skills rule","") | M11: none | N11: Strengths: experience in band, role-relevant achievement. Gaps: degree off-spec. Qualification: MBA Marketing partly relevant (12/25). Experience: 3.5 yrs, inside 2-4 band (25/25). Skills (16/40): has Excel, Power BI; missing financial modelling, valuation, variance analysis. Achievement: cut reporting time 40% via Excel automation (10/10). | O11: test financial modelling, valuation, variance analysis | P11: =A11&"|"&C11 -> CV089|JD3
A12: CV044 | B12: =INDEX(Resumes!$B$2:$B$101,MATCH(A12,Resumes!$A$2:$A$101,0)) -> Nisha Banerjee | C12: JD3 | D12: =INDEX('Job Descriptions'!$B$2:$B$6,MATCH(C12,'Job Descriptions'!$A$2:$A$6,0)) -> Financial Analyst | E12: 25 | F12: 12 | G12: 12 | H12: 10 | I12: =SUM(E12:H12) -> 59 | J12: =IF(AND(I12>=SL_CUT,G12>=SL_SKILL),"Shortlist",IF(AND(I12>=RV_CUT,G12>=RV_SKILL),"Review","Not shortlisted")) -> Review | K12: =COUNTIFS($C$4:$C$203,C12,$I$4:$I$203,">"&I12)+1 -> 9 | L12: =IF(OR(AND(I12>=SL_CUT,G12<SL_SKILL),AND(I12>=RV_CUT,G12<RV_SKILL)),"Capped by minimum-skills rule","") | M12: Power BI <- Power BI used in achievement | N12: Strengths: right degree, role-relevant achievement. Gaps: over-experienced for band. Qualification: CA meets requirement (25/25). Experience: 7.2 yrs, 3.2 above 2-4 band (12/25). Skills (12/40): has valuation; partial: Power BI <- Power BI used in achievement; missing financial modelling, Excel, variance analysis. Achievement: Power BI dashboard for 30 managers (10/10). | O12: test financial modelling, Excel, variance analysis; confirm Power BI (partial credit); check fit/expectations given seniority | P12: =A12&"|"&C12 -> CV044|JD3
A13: CV096 | B13: =INDEX(Resumes!$B$2:$B$101,MATCH(A13,Resumes!$A$2:$A$101,0)) -> Vivaan Nair | C13: JD3 | D13: =INDEX('Job Descriptions'!$B$2:$B$6,MATCH(C13,'Job Descriptions'!$A$2:$A$6,0)) -> Financial Analyst | E13: 25 | F13: 25 | G13: 8 | H13: 0 | I13: =SUM(E13:H13) -> 58 | J13: =IF(AND(I13>=SL_CUT,G13>=SL_SKILL),"Shortlist",IF(AND(I13>=RV_CUT,G13>=RV_SKILL),"Review","Not shortlisted")) -> Review | K13: =COUNTIFS($C$4:$C$203,C13,$I$4:$I$203,">"&I13)+1 -> 10 | L13: =IF(OR(AND(I13>=SL_CUT,G13<SL_SKILL),AND(I13>=RV_CUT,G13<RV_SKILL)),"Capped by minimum-skills rule","") | M13: none | N13: Strengths: right degree, experience in band. Gaps: weak skill match. Qualification: MBA Finance meets requirement (25/25). Experience: 2.4 yrs, inside 2-4 band (25/25). Skills (8/40): has Excel; missing financial modelling, valuation, variance analysis, Power BI. Achievement: none listed (0/10). | O13: test financial modelling, valuation, variance analysis, Power BI | P13: =A13&"|"&C13 -> CV096|JD3
A14: CV005 | B14: =INDEX(Resumes!$B$2:$B$101,MATCH(A14,Resumes!$A$2:$A$101,0)) -> Farhan Patil | C14: JD3 | D14: =INDEX('Job Descriptions'!$B$2:$B$6,MATCH(C14,'Job Descriptions'!$A$2:$A$6,0)) -> Financial Analyst | E14: 6 | F14: 25 | G14: 16 | H14: 10 | I14: =SUM(E14:H14) -> 57 | J14: =IF(AND(I14>=SL_CUT,G14>=SL_SKILL),"Shortlist",IF(AND(I14>=RV_CUT,G14>=RV_SKILL),"Review","Not shortlisted")) -> Review | K14: =COUNTIFS($C$4:$C$203,C14,$I$4:$I$203,">"&I14)+1 -> 11 | L14: =IF(OR(AND(I14>=SL_CUT,G14<SL_SKILL),AND(I14>=RV_CUT,G14<RV_SKILL)),"Capped by minimum-skills rule","") | M14: none | N14: Strengths: experience in band, role-relevant achievement. Gaps: degree off-spec. Qualification: BBA not the required degree (6/25). Experience: 3 yrs, inside 2-4 band (25/25). Skills (16/40): has financial modelling, Power BI; missing Excel, valuation, variance analysis. Achievement: Power BI dashboard for 30 managers (10/10). | O14: test Excel, valuation, variance analysis | P14: =A14&"|"&C14 -> CV005|JD3
A15: CV009 | B15: =INDEX(Resumes!$B$2:$B$101,MATCH(A15,Resumes!$A$2:$A$101,0)) -> Vivaan Das | C15: JD3 | D15: =INDEX('Job Descriptions'!$B$2:$B$6,MATCH(C15,'Job Descriptions'!$A$2:$A$6,0)) -> Financial Analyst | E15: 25 | F15: 20 | G15: 8 | H15: 4 | I15: =SUM(E15:H15) -> 57 | J15: =IF(AND(I15>=SL_CUT,G15>=SL_SKILL),"Shortlist",IF(AND(I15>=RV_CUT,G15>=RV_SKILL),"Review","Not shortlisted")) -> Review | K15: =COUNTIFS($C$4:$C$203,C15,$I$4:$I$203,">"&I15)+1 -> 11 | L15: =IF(OR(AND(I15>=SL_CUT,G15<SL_SKILL),AND(I15>=RV_CUT,G15<RV_SKILL)),"Capped by minimum-skills rule","") | M15: none | N15: Strengths: right degree. Gaps: over-experienced for band, weak skill match. Qualification: MBA Finance meets requirement (25/25). Experience: 5.8 yrs, 1.8 above 2-4 band (20/25). Skills (8/40): has valuation; missing financial modelling, Excel, variance analysis, Power BI. Achievement: vendor on-time delivery 78%->92% (4/10). | O15: test financial modelling, Excel, variance analysis, Power BI; check fit/expectations given seniority | P15: =A15&"|"&C15 -> CV009|JD3
... A203: CV078 | B203: =INDEX(Resumes!$B$2:$B$101,MATCH(A203,Resumes!$A$2:$A$101,0)) -> Deepak Rao | C203: JD5 | D203: =INDEX('Job Descriptions'!$B$2:$B$6,MATCH(C203,'Job Descriptions'!$A$2:$A$6,0)) -> Product Manager - Fintech | E203: 5 | F203: 0 | G203: 0 | H203: 4 | I203: =SUM(E203:H203) -> 9 | J203: =IF(AND(I203>=SL_CUT,G203>=SL_SKILL),"Shortlist",IF(AND(I203>=RV_CUT,G203>=RV_SKILL),"Review","Not shortlisted")) -> Not shortlisted | K203: =COUNTIFS($C$4:$C$203,C203,$I$4:$I$203,">"&I203)+1 -> 100 | L203: =IF(OR(AND(I203>=SL_CUT,G203<SL_SKILL),AND(I203>=RV_CUT,G203<RV_SKILL)),"Capped by minimum-skills rule","") | M203: none | N203: No clear strengths. Gaps: degree off-spec, under-experienced, weak skill match. Qualification: BBA not the required degree (5/25). Experience: 0.4 yrs, 2.6 below 3-6 band (0/25). Skills (0/40): has none of the 5; missing product roadmap, user research, SQL, agile, UPI/payments. Achievement: vendor on-time delivery 78%->92% (4/10). | O203: test product roadmap, user research, SQL, agile, UPI/payments; check depth of hands-on experience | P203: =A203&"|"&C203 -> CV078|JD5

Sheet Scoring Prompt
A1: Scoring prompt (final, v3.1) and rubric
A2: The AI fills the four component scores, partial credit, reason and probes. Excel adds them up and makes the decision. Yellow cells are settings you can change.
A4: Prompt part | B4: Prompt text (exact) - paste parts 1-7 together as one message, once per resume-JD pair
A5: 1. Role | B5: You are a fair, evidence-based resume screener supporting a hiring team. You score; humans decide.
A6: 2. Task | B6: Score ONE resume against ONE job description using only the rubric below. Use only facts written in the resume. If something is not stated, give it no credit - do not guess.
A7: 3. Inputs | B7: JOB DESCRIPTION: {jd_id} | {role} | {requirements} RESUME: {candidate_id} | {resume_summary} QUALIFICATION TABLE and ACHIEVEMENT TABLE for this JD: {paste the matching columns from the tables below}
A8: 4. Rubric (100 pts) | B8: Qualification 0-25: from the qualification table. Experience 0-25: inside the JD band = 25; below by up to 1 yr = 15; below by more than 1 and up to 2 yrs = 8; below by more than 2 yrs = 0; above by up to 2 yrs = 20; above by more than 2 yrs = 12. Skills 0-40: 8 points for each of the 5 required skills that appears in 'Key skills'. Achievement 0-10: from the achievement table.
A9: 5. Partial credit | B9: If a required skill is NOT in 'Key skills', give 4 points only when one of these rules applies (never more than 8 for one skill): JD3: Tableau listed -> Power BI; Power BI named in the achievement -> Power BI; Excel named in the achievement -> Excel. JD5: most recent employer is a fintech start-up or a bank (sector exposure) -> UPI/payments; A/B testing listed -> user research. List every partial credit as 'skill <- evidence'.
A10: 6. Do not use | B10: Ignore and never mention: name, gender, age, religion, caste, region or language, marital or family status, institute tier or college name, career gaps or their reasons, employer brand or prestige. These are not job requirements.
A11: 7. Output format | B11: Return exactly one line, pipe-separated, no other text: candidate_id | jd_id | qual_pts | exp_pts | skill_pts | ach_pts | partial_credit ('none' if none) | reason (max 70 words: 'Strengths: ... Gaps: ...', then one clause per rubric line naming skills found and missing) | interview_probes Do NOT compute the total or a decision - the spreadsheet does that.
A13: Decision rules - applied by Excel formulas, not by the AI
A14: Setting | B14: Value | C14: Meaning
A15: Shortlist: minimum total | B15: 60 | C15: Total score at or above this goes to Shortlist (interview) if the skills minimum below is also met.
A16: Shortlist: minimum skill points | B16: 12 | C16: Added in v3.1: at least 1.5 required skills of evidence (e.g. one listed + one partial).
A17: Review: minimum total | B17: 55 | C17: Total at or above this (but below Shortlist) goes to a human recruiter. Nobody in this band is auto-rejected.
A18: Review: minimum skill points | B18: 8 | C18: Added in v3.1: at least one required skill evidenced. Stops degree + years alone from reaching Review.
A20: Role parameters (the two roles screened)
A21: jd_id | B21: role | C21: band_low (yrs) | D21: band_high (yrs) | E21: skill_1 | F21: skill_2 | G21: skill_3 | H21: skill_4 | I21: skill_5
A22: JD3 | B22: Financial Analyst | C22: 2 | D22: 4 | E22: financial modelling | F22: Excel | G22: valuation | H22: variance analysis | I22: Power BI
A23: JD5 | B23: Product Manager - Fintech | C23: 3 | D23: 6 | E23: product roadmap | F23: user research | G23: SQL | H23: agile | I23: UPI/payments
A25: Qualification points (0-25)
A26: qualification | B26: JD3 | C26: JD5 | D26: Rationale
A27: MBA Finance | B27: 25 | C27: 15 | D27: JD3: required. JD5: MBA without stated tech background.
A28: CA | B28: 25 | C28: 5 | D28: JD3: required (MBA Finance or CA). JD5: not an MBA.
A29: B.Tech + MBA | B29: 12 | C29: 25 | D29: JD3: MBA, specialisation not stated. JD5: exactly "MBA with tech background".
A30: MBA Marketing | B30: 12 | C30: 15 | D30: MBA, but not the specialisation asked for.
A31: MBA HR | B31: 12 | C31: 15 | D31: MBA, but not the specialisation asked for.
A32: MBA Operations | B32: 12 | C32: 15 | D32: MBA, but not the specialisation asked for.
A33: B.Com | B33: 8 | C33: 5 | D33: Commerce graduate: some finance grounding for JD3, none of the MBA ask.
A34: BBA | B34: 6 | C34: 5 | D34: Business graduate, no MBA.
A36: Achievement relevance points (0-10)
A37: achievement (exact text in resume) | B37: JD3 | C37: JD5 | D37: Rationale
A38: built a Power BI sales dashboard used by 30 managers | B38: 10 | C38: 7 | D38: JD3: uses a required tool at scale. JD5: shipped a data product with real user adoption.
A39: cut reporting time by 40% by automating Excel reports | B39: 10 | C39: 6 | D39: JD3: core analyst work in a required tool. JD5: process automation, quantified.
A40: improved vendor on-time delivery from 78% to 92% | B40: 4 | C40: 4 | D40: Quantified impact, but in operations, not the target function.
A41: handled 120 hires in one year | B41: 3 | C41: 3 | D41: Quantified, but HR work unrelated to either role.
A42: led a 5-member campus marketing team | B42: 3 | C42: 5 | D42: Leadership at campus level; more relevant to a PM (JD5) than an analyst.
A43: no major achievement listed | B43: 0 | C43: 0 | D43: No evidence to score.
A45: Experience points (0-25)
A46: Rule | B46: Points
...

Sheet Prompt Iterations
A1: Prompt iterations - v1 to v3.1, with rejected outputs kept
A2: Each round: exact prompt, what it was tested on, what failed (with numbers), and the change made.
A4: Version | B4: Prompt text (exact) | C4: Tested on | D4: What worked | E4: What failed (evidence) | F4: Change made next | G4: Status
A5: v1 | B5: Score this resume out of 100 for the job description below and give reasons. JOB DESCRIPTION: JD3 Financial Analyst - MBA Finance or CA; 2-4 years; skills: financial modelling, Excel, valuation, variance analysis, Power BI. RESUME: {resume_summary} | C5: Pilot: 5 JD3 resumes (CV015, CV023, CV043, CV097, CV073) | D5: Fast; reasons were readable and picked up the main skills. | E5: No score breakdown, so no number could be verified. 4 of 5 reasons cited institute tier or a career gap. Average 66 vs 49 under the final rubric (same 5 resumes): unanchored and inflated. Free text could not be pasted into Excel. | F5: Added a fixed 100-point rubric and a one-line pipe-separated output. | G5: Rejected
A6: v2 | B6: You are a resume screener. Score the resume against the job description using this rubric (100 points): Qualification 0-25 (exact required degree 25, other MBA 12-15, other degree 5-8); Experience 0-25 (inside band 25; up to 1 yr below 15; 1-2 yrs below 8; more 0; up to 2 yrs above 20; more 12); Skills 0-40 (8 points for each required skill that appears in the Key skills list); Achievement 0-10 (relevance of the listed achievement to the role). Then adjust: +5 for a tier-1 institute, -5 for a tier-3 institute, -5 for any career gap. Output one line: candidate_id | jd_id | qual | exp | skills | achievement | adjustment | total | reason (max 40 words). JOB DESCRIPTION: {jd} RESUME: {resume_summary} | C6: All 200 resume-JD pairs | D6: Every component visible and checkable; output pasted straight into Excel. | E6: Tier/gap adjustments are not job requirements: on their own they flip 23 of 200 decisions and halve the JD3 female shortlist rate (7.7% to 3.8%) - see Fairness Audit. Exact-match skills ignored real evidence (Tableau for Power BI, fintech employer for payments): 77 of 200 pairs under-scored by 4-8 points. AI also added up the total itself (arithmetic risk). | F6: Removed adjustments; added a DO-NOT-USE list; added 5 explicit partial-credit rules; moved total and decision to Excel. | G6: Rejected
A7: v3 | B7: Parts 1-7 on 'Scoring Prompt' (final text), without the minimum-skills rule. | C7: All 200 pairs + 20-row manual spot-check | D7: Scores reproduced exactly by independent formulas; reasons name skills found and missing; 0 reasons mention tier, gap, gender or the candidate name. | E7: Spot-check: CV022 (0 of 5 JD5 skills) reached the Review band on degree + years alone (57); CV040 was shortlisted for JD3 with 1 of 5 skills (63). Reasons gave no hint why a strong-looking total was held back. | F7: Added minimum-skills gate in the Excel decision formula (not in the prompt) and a 'decision note' column. | G7: Superseded
A8: v3.1 | B8: Same prompt as v3 + Excel decision rule: Shortlist needs total >= 60 AND skill pts >= 12; Review needs total >= 55 AND skill pts >= 8. | C8: All 200 pairs | D8: Changed exactly 2 decisions (CV040 JD3 Shortlist -> Review; CV022 JD5 Review -> Not shortlisted). Thresholds are editable cells, so the hiring manager can tune them. | E8: Partial credit is used in 77 of 200 pairs, so that evidence must be confirmed at interview (probe column). | F8: Final - no prompt change needed. | G8: Kept
A10: v1 pilot outputs (verbatim, rejected) compared with the final score
A11: candidate_id | B11: v1 output (Claude, holistic, no rubric) | C11: v1 score | D11: v3.1 score | E11: Difference | F11: Non-job attribute cited?
A12: CV015 | B12: Score: 78/100. Aarav is a strong candidate with an MBA in Finance from a tier-1 institute and nearly 7 years of experience. He has valuation and Excel skills, which are core to the role. He lacks financial modelling and Power BI. His experience exceeds the 2-4 year requirement, so he may be overqualified. | C12: 78 | D12: =INDEX('Scored Shortlist'!$I$4:$I$203,MATCH(A12&"|JD3",'Scored Shortlist'!$P$4:$P$203,0)) -> 53 | E12: =C12-D12 -> 25 | F12: Yes - institute tier
A13: CV023 | B13: Score: 50/100. Suresh has the right degree and financial modelling skills, but with only 0.1 years of experience he is essentially a fresher. Being from a tier-3 institute, he may need more training. | C13: 50 | D13: =INDEX('Scored Shortlist'!$I$4:$I$203,MATCH(A13&"|JD3",'Scored Shortlist'!$P$4:$P$203,0)) -> 41 | E13: =C13-D13 -> 9 | F13: Yes - institute tier
A14: CV043 | B14: Score: 60/100. Isha has an MBA Finance and valuation skills, and Tableau is similar to Power BI. She is just under 2 years of experience and has a 6-month career gap, which may be a concern. | C14: 60 | D14: =INDEX('Scored Shortlist'!$I$4:$I$203,MATCH(A14&"|JD3",'Scored Shortlist'!$P$4:$P$203,0)) -> 55 | E14: =C14-D14 -> 5 | F14: Yes - career gap
A15: CV097 | B15: Score: 62/100. Manish has strong financial modelling and valuation skills and a lot of experience, but does not have an MBA or CA. | C15: 62 | D15: =INDEX('Scored Shortlist'!$I$4:$I$203,MATCH(A15&"|JD3",'Scored Shortlist'!$P$4:$P$203,0)) -> 40 | E15: =C15-D15 -> 22 | F15: No
A16: CV073 | B16: Score: 80/100. Gauri is a Chartered Accountant from a tier-1 institute with 7.7 years of experience and strong financial modelling and Excel skills. Excellent fit, though she may be overqualified. | C16: 80 | D16: =INDEX('Scored Shortlist'!$I$4:$I$203,MATCH(A16&"|JD3",'Scored Shortlist'!$P$4:$P$203,0)) -> 57 | E16: =C16-D16 -> 23 | F16: Yes - institute tier
A17: Average | C17: =AVERAGE(C12:C16) -> 66 | D17: =AVERAGE(D12:D16) -> 49.2 | E17: =C17-D17 -> 16.8 | F17: =COUNTIF(F12:F16,"Yes*")&" of 5 cite a non-job attribute" -> 4 of 5 cite a non-job attribute
A19: Guidelines - first draft (rejected) and why
A20: Version | B20: Prompt (exact) | C20: Output (verbatim) | D20: What failed | E20: Change made next
A21: G-v1 | B21: Write guidelines for fair AI-assisted resume screening. | C21: 1. Remove names and photos from resumes. 2. Use diverse training data. 3. Regularly audit the AI for bias. 4. Keep a human in the loop. 5. Be transparent with candidates. 6. Comply with data protection laws. | D21: Generic: no thresholds, owners, or checks. 'Diverse training data' does not apply (no model is trained here). Nothing tied to this project's evidence. | E21: Re-prompted: each rule must be specific to this screener, cite a number from this project, and name an owner and a check frequency. Result on 'Guidelines'.

Sheet Rule Check
A1: Rule check - independent Excel re-computation of every AI score
A2: Recomputes qualification, experience, exact-skill and achievement points from the raw Resumes sheet with formulas, then checks the AI components. Skill difference must equal 4 x number of partial credits.
A3: candidate_id | B3: jd_id | C3: qualification | D3: years | E3: skills (from Resumes) | F3: resume_summary | G3: achievement (MID/FIND) | H3: band_low | I3: band_high | J3: rule qual | K3: rule exp | L3: exact skills found | M3: rule skill pts | N3: rule ach | O3: rule total | P3: AI qual | Q3: AI exp | R3: AI skill | S3: AI ach | T3: AI total | U3: partials (AI) | V3: qual ok | W3: exp ok | X3: ach ok | Y3: skill diff | Z3: expected diff | AA3: skill ok | AB3: ROW CHECK | AC3: decision if exact-match only | AD3: first name in reason?
A4: ='Scored Shortlist'!A4 -> CV051 | B4: ='Scored Shortlist'!C4 -> JD3 | C4: =INDEX(Resumes!$D$2:$D$101,MATCH(A4,Resumes!$A$2:$A$101,0)) -> CA | D4: =INDEX(Resumes!$E$2:$E$101,MATCH(A4,Resumes!$A$2:$A$101,0)) -> 3.4 | E4: =INDEX(Resumes!$G$2:$G$101,MATCH(A4,Resumes!$A$2:$A$101,0)) -> valuation, Excel, campaign management, public speaking, Tableau, Google Analytics, product roadmap | F4: =INDEX(Resumes!$I$2:$I$101,MATCH(A4,Resumes!$A$2:$A$101,0)) -> Shreya Shah, CA from a tier-3 institute. 3.4 years of experience, most recently at an IT services firm. Key skills: valuation, Excel, campaign management, public speaking, Tableau, Google Analytics, product roadmap. Achievement: led a 5-member campus marketing team. Career gap: 1-year career break (family). | G4: =MID(F4,FIND("Achievement: ",F4)+13,FIND(". Career gap",F4)-FIND("Achievement: ",F4)-13) -> led a 5-member campus marketing team | H4: =INDEX('Scoring Prompt'!$C$22:$C$23,MATCH(B4,'Scoring Prompt'!$A$22:$A$23,0)) -> 2 | I4: =INDEX('Scoring Prompt'!$D$22:$D$23,MATCH(B4,'Scoring Prompt'!$A$22:$A$23,0)) -> 4 | J4: =INDEX('Scoring Prompt'!$B$27:$C$34,MATCH(C4,'Scoring Prompt'!$A$27:$A$34,0),MATCH(B4,'Scoring Prompt'!$B$26:$C$26,0)) -> 25 | K4: =IF(AND(D4>=H4,D4<=I4),'Scoring Prompt'!$B$47,IF(D4<H4,IF(H4-D4<=1,'Scoring Prompt'!$B$48,IF(H4-D4<=2,'Scoring Prompt'!$B$49,'Scoring Prompt'!$B$50)),IF(D4-I4<=2,'Scoring Prompt'!$B$51,'Scoring Prompt'!$B$52))) -> 25 | L4: =IF(B4="JD3",SUMPRODUCT(--ISNUMBER(SEARCH('Scoring Prompt'!$E$22:$I$22,E4))),SUMPRODUCT(--ISNUMBER(SEARCH('Scoring Prompt'!$E$23:$I$23,E4)))) -> 2 | M4: =8*L4 -> 16 | N4: =INDEX('Scoring Prompt'!$B$38:$C$43,MATCH(G4,'Scoring Prompt'!$A$38:$A$43,0),MATCH(B4,'Scoring Prompt'!$B$37:$C$37,0)) -> 3 | O4: =J4+K4+M4+N4 -> 69 | P4: ='Scored Shortlist'!E4 -> 25 | Q4: ='Scored Shortlist'!F4 -> 25 | R4: ='Scored Shortlist'!G4 -> 20 | S4: ='Scored Shortlist'!H4 -> 3 | T4: ='Scored Shortlist'!I4 -> 73 | U4: =IF('Scored Shortlist'!M4="none",0,(LEN('Scored Shortlist'!M4)-LEN(SUBSTITUTE('Scored Shortlist'!M4,"<-","")))/2) -> 1 | V4: =IF(P4=J4,1,0) -> 1 | W4: =IF(Q4=K4,1,0) -> 1 | X4: =IF(S4=N4,1,0) -> 1 | Y4: =R4-M4 -> 4 | Z4: =4*U4 -> 4 | AA4: =IF(Y4=Z4,1,0) -> 1 | AB4: =IF(V4+W4+X4+AA4=4,"OK","CHECK") -> OK | AC4: =IF(AND(O4>=SL_CUT,M4>=SL_SKILL),"Shortlist",IF(AND(O4>=RV_CUT,M4>=RV_SKILL),"Review","Not shortlisted")) -> Shortlist | AD4: =IF(ISNUMBER(SEARCH(" "&LEFT('Scored Shortlist'!B4,FIND(" ",'Scored Shortlist'!B4)-1)&" "," "&'Scored Shortlist'!N4&" ")),"YES","no") -> no
A5: ='Scored Shortlist'!A5 -> CV019 | B5: ='Scored Shortlist'!C5 -> JD3 | C5: =INDEX(Resumes!$D$2:$D$101,MATCH(A5,Resumes!$A$2:$A$101,0)) -> MBA Finance | D5: =INDEX(Resumes!$E$2:$E$101,MATCH(A5,Resumes!$A$2:$A$101,0)) -> 3.5 | E5: =INDEX(Resumes!$G$2:$G$101,MATCH(A5,Resumes!$A$2:$A$101,0)) -> SEO, product roadmap, A/B testing, Excel, user research | F5: =INDEX(Resumes!$I$2:$I$101,MATCH(A5,Resumes!$A$2:$A$101,0)) -> Rahul Pawar, MBA Finance from a tier-3 institute. 3.5 years of experience, most recently at a consulting firm. Key skills: SEO, product roadmap, A/B testing, Excel, user research. Achievement: built a Power BI sales dashboard used by 30 managers. Career gap: None. | G5: =MID(F5,FIND("Achievement: ",F5)+13,FIND(". Career gap",F5)-FIND("Achievement: ",F5)-13) -> built a Power BI sales dashboard used by 30 managers | H5: =INDEX('Scoring Prompt'!$C$22:$C$23,MATCH(B5,'Scoring Prompt'!$A$22:$A$23,0)) -> 2 | I5: =INDEX('Scoring Prompt'!$D$22:$D$23,MATCH(B5,'Scoring Prompt'!$A$22:$A$23,0)) -> 4 | J5: =INDEX('Scoring Prompt'!$B$27:$C$34,MATCH(C5,'Scoring Prompt'!$A$27:$A$34,0),MATCH(B5,'Scoring Prompt'!$B$26:$C$26,0)) -> 25 | K5: =IF(AND(D5>=H5,D5<=I5),'Scoring Prompt'!$B$47,IF(D5<H5,IF(H5-D5<=1,'Scoring Prompt'!$B$48,IF(H5-D5<=2,'Scoring Prompt'!$B$49,'Scoring Prompt'!$B$50)),IF(D5-I5<=2,'Scoring Prompt'!$B$51,'Scoring Prompt'!$B$52))) -> 25 | L5: =IF(B5="JD3",SUMPRODUCT(--ISNUMBER(SEARCH('Scoring Prompt'!$E$22:$I$22,E5))),SUMPRODUCT(--ISNUMBER(SEARCH('Scoring Prompt'!$E$23:$I$23,E5)))) -> 1 | M5: =8*L5 -> 8 | N5: =INDEX('Scoring Prompt'!$B$38:$C$43,MATCH(G5,'Scoring Prompt'!$A$38:$A$43,0),MATCH(B5,'Scoring Prompt'!$B$37:$C$37,0)) -> 10 | O5: =J5+K5+M5+N5 -> 68 | P5: ='Scored Shortlist'!E5 -> 25 | Q5: ='Scored Shortlist'!F5 -> 25 | R5: ='Scored Shortlist'!G5 -> 12 | S5: ='Scored Shortlist'!H5 -> 10 | T5: ='Scored Shortlist'!I5 -> 72 | U5: =IF('Scored Shortlist'!M5="none",0,(LEN('Scored Shortlist'!M5)-LEN(SUBSTITUTE('Scored Shortlist'!M5,"<-","")))/2) -> 1 | V5: =IF(P5=J5,1,0) -> 1 | W5: =IF(Q5=K5,1,0) -> 1 | X5: =IF(S5=N5,1,0) -> 1 | Y5: =R5-M5 -> 4 | Z5: =4*U5 -> 4 | AA5: =IF(Y5=Z5,1,0) -> 1 | AB5: =IF(V5+W5+X5+AA5=4,"OK","CHECK") -> OK | AC5: =IF(AND(O5>=SL_CUT,M5>=SL_SKILL),"Shortlist",IF(AND(O5>=RV_CUT,M5>=RV_SKILL),"Review","Not shortlisted")) -> Review | AD5: =IF(ISNUMBER(SEARCH(" "&LEFT('Scored Shortlist'!B5,FIND(" ",'Scored Shortlist'!B5)-1)&" "," "&'Scored Shortlist'!N5&" ")),"YES","no") -> no
A6: ='Scored Shortlist'!A6 -> CV025 | B6: ='Scored Shortlist'!C6 -> JD3 | C6: =INDEX(Resumes!$D$2:$D$101,MATCH(A6,Resumes!$A$2:$A$101,0)) -> MBA Finance | D6: =INDEX(Resumes!$E$2:$E$101,MATCH(A6,Resumes!$A$2:$A$101,0)) -> 5.5 | E6: =INDEX(Resumes!$G$2:$G$101,MATCH(A6,Resumes!$A$2:$A$101,0)) -> recruitment, Tableau, financial modelling, inventory planning, vendor management, content writing, valuation, Python | F6: =INDEX(Resumes!$I$2:$I$101,MATCH(A6,Resumes!$A$2:$A$101,0)) -> Kavya Verma, MBA Finance from a tier-3 institute. 5.5 years of experience, most recently at a consulting firm. Key skills: recruitment, Tableau, financial modelling, inventory planning, vendor management, content writing, valuation, Python. Achievement: handled 120 hires in one year. Career gap: 6-month gap (exam preparation). | G6: =MID(F6,FIND("Achievement: ",F6)+13,FIND(". Career gap",F6)-FIND("Achievement: ",F6)-13) -> handled 120 hires in one year | H6: =INDEX('Scoring Prompt'!$C$22:$C$23,MATCH(B6,'Scoring Prompt'!$A$22:$A$23,0)) -> 2 | I6: =INDEX('Scoring Prompt'!$D$22:$D$23,MATCH(B6,'Scoring Prompt'!$A$22:$A$23,0)) -> 4 | J6: =INDEX('Scoring Prompt'!$B$27:$C$34,MATCH(C6,'Scoring Prompt'!$A$27:$A$34,0),MATCH(B6,'Scoring Prompt'!$B$26:$C$26,0)) -> 25 | K6: =IF(AND(D6>=H6,D6<=I6),'Scoring Prompt'!$B$47,IF(D6<H6,IF(H6-D6<=1,'Scoring Prompt'!$B$48,IF(H6-D6<=2,'Scoring Prompt'!$B$49,'Scoring Prompt'!$B$50)),IF(D6-I6<=2,'Scoring Prompt'!$B$51,'Scoring Prompt'!$B$52))) -> 20 | L6: =IF(B6="JD3",SUMPRODUCT(--ISNUMBER(SEARCH('Scoring Prompt'!$E$22:$I$22,E6))),SUMPRODUCT(--ISNUMBER(SEARCH('Scoring Prompt'!$E$23:$I$23,E6)))) -> 2 | M6: =8*L6 -> 16 | N6: =INDEX('Scoring Prompt'!$B$38:$C$43,MATCH(G6,'Scoring Prompt'!$A$38:$A$43,0),MATCH(B6,'Scoring Prompt'!$B$37:$C$37,0)) -> 3 | O6: =J6+K6+M6+N6 -> 64 | P6: ='Scored Shortlist'!E6 -> 25 | Q6: ='Scored Shortlist'!F6 -> 20 | R6: ='Scored Shortlist'!G6 -> 20 | S6: ='Scored Shortlist'!H6 -> 3 | T6: ='Scored Shortlist'!I6 -> 68 | U6: =IF('Scored Shortlist'!M6="none",0,(LEN('Scored Shortlist'!M6)-LEN(SUBSTITUTE('Scored Shortlist'!M6,"<-","")))/2) -> 1 | V6: =IF(P6=J6,1,0) -> 1 | W6: =IF(Q6=K6,1,0) -> 1 | X6: =IF(S6=N6,1,0) -> 1 | Y6: =R6-M6 -> 4 | Z6: =4*U6 -> 4 | AA6: =IF(Y6=Z6,1,0) -> 1 | AB6: =IF(V6+W6+X6+AA6=4,"OK","CHECK") -> OK | AC6: =IF(AND(O6>=SL_CUT,M6>=SL_SKILL),"Shortlist",IF(AND(O6>=RV_CUT,M6>=RV_SKILL),"Review","Not shortlisted")) -> Shortlist | AD6: =IF(ISNUMBER(SEARCH(" "&LEFT('Scored Shortlist'!B6,FIND(" ",'Scored Shortlist'!B6)-1)&" "," "&'Scored Shortlist'!N6&" ")),"YES","no") -> no
A7: ='Scored Shortlist'!A7 -> CV055 | B7: ='Scored Shortlist'!C7 -> JD3 | C7: =INDEX(Resumes!$D$2:$D$101,MATCH(A7,Resumes!$A$2:$A$101,0)) -> CA | D7: =INDEX(Resumes!$E$2:$E$101,MATCH(A7,Resumes!$A$2:$A$101,0)) -> 7.3 | E7: =INDEX(Resumes!$G$2:$G$101,MATCH(A7,Resumes!$A$2:$A$101,0)) -> HR analytics, Tableau, employee relations, A/B testing, valuation, SQL, Google Analytics, Excel | F7: =INDEX(Resumes!$I$2:$I$101,MATCH(A7,Resumes!$A$2:$A$101,0)) -> Joseph Jadhav, CA from a tier-3 institute. 7.3 years of experience, most recently at a bank. Key skills: HR analytics, Tableau, employee relations, A/B testing, valuation, SQL, Google Analytics, Excel. Achievement: cut reporting time by 40% by automating Excel reports. Career gap: None. | G7: =MID(F7,FIND("Achievement: ",F7)+13,FIND(". Career gap",F7)-FIND("Achievement: ",F7)-13) -> cut reporting time by 40% by automating Excel reports | H7: =INDEX('Scoring Prompt'!$C$22:$C$23,MATCH(B7,'Scoring Prompt'!$A$22:$A$23,0)) -> 2 | I7: =INDEX('Scoring Prompt'!$D$22:$D$23,MATCH(B7,'Scoring Prompt'!$A$22:$A$23,0)) -> 4 | J7: =INDEX('Scoring Prompt'!$B$27:$C$34,MATCH(C7,'Scoring Prompt'!$A$27:$A$34,0),MATCH(B7,'Scoring Prompt'!$B$26:$C$26,0)) -> 25 | K7: =IF(AND(D7>=H7,D7<=I7),'Scoring Prompt'!$B$47,IF(D7<H7,IF(H7-D7<=1,'Scoring Prompt'!$B$48,IF(H7-D7<=2,'Scoring Prompt'!$B$49,'Scoring Prompt'!$B$50)),IF(D7-I7<=2,'Scoring Prompt'!$B$51,'Scoring Prompt'!$B$52))) -> 12 | L7: =IF(B7="JD3",SUMPRODUCT(--ISNUMBER(SEARCH('Scoring Prompt'!$E$22:$I$22,E7))),SUMPRODUCT(--ISNUMBER(SEARCH('Scoring Prompt'!$E$23:$I$23,E7)))) -> 2 | M7: =8*L7 -> 16 | N7: =INDEX('Scoring Prompt'!$B$38:$C$43,MATCH(G7,'Scoring Prompt'!$A$38:$A$43,0),MATCH(B7,'Scoring Prompt'!$B$37:$C$37,0)) -> 10 | O7: =J7+K7+M7+N7 -> 63 | P7: ='Scored Shortlist'!E7 -> 25 | Q7: ='Scored Shortlist'!F7 -> 12 | R7: ='Scored Shortlist'!G7 -> 20 | S7: ='Scored Shortlist'!H7 -> 10 | T7: ='Scored Shortlist'!I7 -> 67 | U7: =IF('Scored Shortlist'!M7="none",0,(LEN('Scored Shortlist'!M7)-LEN(SUBSTITUTE('Scored Shortlist'!M7,"<-","")))/2) -> 1 | V7: =IF(P7=J7,1,0) -> 1 | W7: =IF(Q7=K7,1,0) -> 1 | X7: =IF(S7=N7,1,0) -> 1 | Y7: =R7-M7 -> 4 | Z7: =4*U7 -> 4 | AA7: =IF(Y7=Z7,1,0) -> 1 | AB7: =IF(V7+W7+X7+AA7=4,"OK","CHECK") -> OK | AC7: =IF(AND(O7>=SL_CUT,M7>=SL_SKILL),"Shortlist",IF(AND(O7>=RV_CUT,M7>=RV_SKILL),"Review","Not shortlisted")) -> Shortlist | AD7: =IF(ISNUMBER(SEARCH(" "&LEFT('Scored Shortlist'!B7,FIND(" ",'Scored Shortlist'!B7)-1)&" "," "&'Scored Shortlist'!N7&" ")),"YES","no") -> no
